<!DOCTYPE html>
<html lang="en">

<head>
  <meta charset="UTF-8">
  <meta name="viewport" content="width=device-width,initial-scale=1.0">
  <title>Async Await</title>
  <link rel="stylesheet" href="../base.css">
</head>

<body>
  <script>
    function wait(ms = 0) {
      return new Promise((resolve) => {
        setTimeout(resolve, ms);
      });
    }

    function makePizza(toppings = []) {
      return new Promise((resolve, reject) => {
        // reject if people try with pineapple
        if (toppings.includes('pineapple')) {
          reject('Seriously? Get out 🍍');
        }
        const amountOfTimeToBake = 500 + toppings.length * 200;
        // wait 1 second for the pizza to cook:
        setTimeout(() => {
          // when you are ready, you can resolve this promise
          resolve(`Here is your pizza 🍕 with the toppings ${toppings.join(' ')}`);
        }, amountOfTimeToBake);
        // if something went wrong, we can reject this promise;
      });
    }

    // try catch - works with anything not just async await
    // async function go() {
    //   try {
    //     const pizza = await makePizza(['pineapple']);
    //     console.log(pizza);
    //   } catch (err) {
    //     console.log('ohhh noooo');
    //     console.log(err);
    //   }
    // }

    // mix and match - using await for the data from the promise and catch for the error
    // That approach is helpful when you want to handle the error at the time that you define the
    // function, so you handle it inside of the function.

    // function handleError(err) {
    //   console.log('ohhh noooo');
    //   console.log(err);
    // }

    // async function go() {
    //   const pizza = await makePizza(['pineapple']).catch(handleError);
    //   console.log(pizza);
    // }

    // go();

    // handle error when calling the function
    function handleError(err) {
      console.log('ohhh noooo');
      console.log(err);
    }

    // async function go() {
    //   // window.doesNotExist();
    //   const pizza = await makePizza(['pineapple']);
    //   console.log(pizza);
    // }

    // go().catch(handleError);

    // This is a very important thing about promises in async await.
    // When you mark a function as async, it will immediately return a
    // promise to you.
    // When a function is not marked with async,
    // it is a regular function that will return the data that you want.
    // async function go() {
    //   const pizza = await makePizza(['pineapple']);
    //   console.log(pizza);
    //   return pizza;
    // }

    // const result = go().catch(handleError);

    // Asynchronous functions will always return a promise themselves,
    // which means we can use the .catch() or the .then() syntax on the async functions if we want.
    // go()
    //   .then((result) => {
    //     console.log(result);
    //   })
    //   .catch(handleError);

    async function go() {
      // window.doesNotExist();
      const pizza = await makePizza(['pineapple']);
      console.log(pizza);
    }

    // catch at runtime
    // go().catch(handleError); // WB use this mostly

    // make a safe function with a High Order Function
    function makeSafe(fn, errorHandler) {
      return function () {
        fn().catch(errorHandler);
      };
    }

    // go(); // this will throw an error

    const safeGo = makeSafe(go, handleError); // this will not throw an error, WB uses this in node

    safeGo();
  </script>
</body>

</html>
